<?xml version="1.0"?>
<robot xmlns:xacro="http://www.ros.org/wiki/xacro">

    <!-- Example link -->
    <xacro:include filename="inertial_macros.xacro"/>

    <!-- Example link -->
    <link name="base_link">
    </link>

    <joint name="base_link" type="fixed">
        <parent link="base_link"/>
        <child link="chassis"/>
        <origin xyz="-0.065 0 0"/>    
    </joint>

    <!--esta huella es para el perimetro la informacion  este es mi volumen y puedo pasar -->
    <joint name="base_footprint_joint" type="fixed">
        <parent link="base_link"/>
        <child link="base_footprint"/>
        <origin xyz="0 0 -0.035"/>    
    </joint>

    <link name="base_footprint">
    </link>



    <!-- chassis link -->
    <link name="chassis">
        <visual>
            <origin xyz="0.15 0 0.075"/>
            <geometry>
                <box size="0.3 0.2 0.15"/>
            </geometry>
            <material name="white"/>
        </visual>
        <collision>
            <origin xyz="0.15 0 0.075"/>
            <geometry>
                <box size="0.3 0.2 0.15"/>
            </geometry>
        </collision>
        <xacro:inertial_box mass="0.5" x="0.3" y="0.3" z="0.15">
            <origin xyz="0.15 0 0.075" rpy="0 0 0"/>
        </xacro:inertial_box>
    </link>
    <gazebo reference="chassis">
        <material>Gazebo/White</material>
    </gazebo>

    <!-- left wheel joint -->
    <joint name="left_wheel_joint" type="continuous">
        <parent link="base_link"/>
        <child link="left_wheel"/>
        <origin xyz="0 0.12 0" rpy="-${pi/2} 0 0"/>
        <axis xyz="0 0 1"/>    
    </joint>

    <!-- left wheel link -->
    <link name="left_wheel">
        <visual>
            <geometry>
                <cylinder radius="0.035" length="0.04"/>
            </geometry>
            <material name="blue"/>
        </visual>
        <collision>
            <geometry>
                <sphere radius="0.035"/>
            </geometry>
        </collision>
        <xacro:inertial_cylinder mass="0.1" length="0.04" radius="0.035">
            <origin xyz="0 0.1 0" rpy="0 0 0"/>
        </xacro:inertial_cylinder>
    </link>
    <gazebo reference="left_wheel">
        <material>Gazebo/Blue</material>
    </gazebo>

    <!-- right wheel joint -->
    <joint name="right_wheel_joint" type="continuous">
        <parent link="base_link"/>
        <child link="right_wheel"/>
        <origin xyz="0 -0.12 0" rpy="${pi/2} 0 0"/>
        <axis xyz="0 0 -1"/>    
    </joint>

    <!-- right wheel link -->
    <link name="right_wheel">
        <visual>
            <geometry>
                <cylinder radius="0.035" length="0.04"/>
            </geometry>
            <material name="blue"/>
        </visual>
        <collision>
            <geometry>
                <sphere radius="0.035"/>
            </geometry>
        </collision>
        <xacro:inertial_cylinder mass="0.1" length="0.04" radius="0.035">
            <origin xyz="0 0 0" rpy="0 0 0"/>
        </xacro:inertial_cylinder>
    </link>
    <gazebo reference="right_wheel">
        <material>Gazebo/Blue</material>
    </gazebo>


    <!-- steering joint -->
    <joint name="steering_joint" type="revolute">
        <limit lower="-1" upper="1" effort="1" velocity="5"/>
        <parent link="base_link"/>
        <child link="steering_wheel"/>
        <origin xyz="0.17 0 0" rpy="0 0 0"/>
        <axis xyz="0 0 1"/>     
    </joint>

    <!-- steering link -->
    <link name="steering_wheel">
        <visual>
            <geometry>
                <cylinder radius="0.001" length="0.001"/>
            </geometry>
            <material name="blue"/>
        </visual>
        <collision>
            <geometry>
                <sphere radius="0.001"/>
            </geometry>
        </collision>
        <xacro:inertial_cylinder mass="0.001" length="0.001" radius="0.001">
            <origin xyz="0 0 0" rpy="0 0 0"/>
        </xacro:inertial_cylinder>
    </link>
    <gazebo reference="steering_wheel">
        <material>Gazebo/Blue</material>
    </gazebo>

    <!-- front left wheel steer joint -->
    <joint name="front_left_steer_joint" type="revolute">
        <limit lower="-1" upper="1" effort="1" velocity="5"/>
        <parent link="base_link"/>
        <child link="left_wheel_steer"/>
        <origin xyz="0.17 0.12 0" rpy="0 0 0"/>
        <axis xyz="0 0 1"/>    
    </joint>

    <!-- front left wheel steer link -->
    <link name="left_wheel_steer">
        <visual>
            <geometry>
                <cylinder radius="0.001" length="0.001"/>
            </geometry>
            <material name="blue"/>
        </visual>
        <collision>
            <geometry>
                <sphere radius="0.001"/>
            </geometry>
        </collision>
        <xacro:inertial_cylinder mass="0.001" length="0.001" radius="0.001">
            <origin xyz="0 0 0" rpy="0 0 0"/>
        </xacro:inertial_cylinder>
    </link>
    <gazebo reference="left_wheel_steer">
        <material>Gazebo/Blue</material>
    </gazebo>

    <!-- front left wheel joint -->
    <joint name="front_left_wheel_joint" type="continuous">
        <parent link="left_wheel_steer"/>
        <child link="F_left_wheel"/>
        <origin xyz="0 0 0" rpy="-${pi/2} 0 0"/>
        <axis xyz="0 0 1"/>    
    </joint>

    <!-- front left wheel link -->
    <link name="F_left_wheel">
        <visual>
            <geometry>
                <cylinder radius="0.035" length="0.04"/>
            </geometry>
            <material name="blue"/>
        </visual>
        <collision>
            <geometry>
                <sphere radius="0.035"/>
            </geometry>
        </collision>
        <xacro:inertial_cylinder mass="0.1" length="0.04" radius="0.035">
            <origin xyz="0 0 0" rpy="0 0 0"/>
        </xacro:inertial_cylinder>
    </link>
    <gazebo reference="F_left_wheel">
        <material>Gazebo/Blue</material>
    </gazebo>

    <!-- front right wheel steer joint -->
    <joint name="front_right_steer_joint" type="revolute">
        <limit lower="-1" upper="1" effort="1" velocity="5"/>
        <parent link="base_link"/>
        <child link="right_wheel_steer"/>
        <origin xyz="0.17 -0.12 0" rpy="0 0 0"/>
        <axis xyz="0 0 1"/>    
    </joint>

    <!-- front left wheel steer link -->
    <link name="right_wheel_steer">
        <visual>
            <geometry>
                <cylinder radius="0.001" length="0.001"/>
            </geometry>
            <material name="blue"/>
        </visual>
        <collision>
            <geometry>
                <sphere radius="0.001"/>
            </geometry>
        </collision>
        <xacro:inertial_cylinder mass="0.001" length="0.001" radius="0.001">
            <origin xyz="0 0 0" rpy="0 0 0"/>
        </xacro:inertial_cylinder>
    </link>
    <gazebo reference="right_wheel_steer">
        <material>Gazebo/Blue</material>
    </gazebo>

    <!--front right wheel joint -->
    <joint name="front_right_wheel_joint" type="continuous">
        <parent link="right_wheel_steer"/>
        <child link="F_right_wheel"/>
        <origin xyz="0 0 0" rpy="${pi/2} 0 0"/>
        <axis xyz="0 0 1"/>    
    </joint>

    <!-- front right wheel link -->
    <link name="F_right_wheel">
        <visual>
            <geometry>
                <cylinder radius="0.035" length="0.04"/>
            </geometry>
            <material name="blue"/>
        </visual>
        <collision>
            <geometry>
                <sphere radius="0.035"/>
            </geometry>
        </collision>
        <xacro:inertial_cylinder mass="0.1" length="0.04" radius="0.035">
            <origin xyz="0 0 0" rpy="0 0 0"/>
        </xacro:inertial_cylinder>
    </link>
    <gazebo reference="F_right_wheel">
        <material>Gazebo/Blue</material>
    </gazebo>
</robot>